Workbook

Sheet QS_DIEN_GIAI_CHI_TIET
B2: DỰ ÁN: CẦU THÔN KHAI HOANG 2 (Km14+363,65 - ĐƯỜNG ĐỒNG VĂN - MỐC 456, HÀ GIANG)
B3: BẢNG DIỄN GIẢI TIÊN LƯỢNG KHỐI LƯỢNG HÌNH HỌC CHI TIẾT (LIÊN KẾT CÔNG THỨC ĐỘNG 100%)
A5: TT | B5: Mã hiệu | C5: Nội dung công tác & Diễn giải hình học cấu kiện | D5: ĐVT | E5: Số lượng (Cấu kiện) | F5: Dài (m) | G5: Rộng (m) | H5: Cao / Dày (m) | I5: Hệ số hình học | J5: Khối lượng (Công thức) | K5: Đơn giá (VNĐ) | L5: Thành tiền (VNĐ)
A6: PHẦN I: CÔNG TÁC MÓNG VÀ MỐ CẦU (M1, M2)
A7: 1 | B7: AB.11413 | C7: Đào hố móng bệ mố ngàm vào nền đá gốc (Mố M1, M2) | D7: m3 | J7: =SUM(J8:J10) -> 76.25 | K7: 145000 | L7: =J7*K7 -> 11056250
C8: - Hố móng bệ mố M1 ngàm đá cấp 4 | D8: m3 | E8: 1 | F8: 6 | G8: 11 | H8: 0.5 | I8: 1 | J8: =E8*F8*G8*H8*I8 -> 33
C9: - Hố móng bệ mố M2 ngàm đá cấp 4 | D9: m3 | E9: 1 | F9: 6.5 | G9: 11 | H9: 0.5 | I9: 1 | J9: =E9*F9*G9*H9*I9 -> 35.75
C10: - Mái vát taluy đào mở rộng hố móng 2 mố | D10: m3 | E10: 2 | F10: 6 | G10: 2.5 | H10: 0.5 | I10: 0.5 | J10: =E10*F10*G10*H10*I10 -> 7.5
A11: 2 | B11: AK.11111 | C11: Đệm đá dăm 4x6 lót móng bệ mố dày 10cm | D11: m3 | J11: =SUM(J12:J13) -> 13.75 | K11: 385000 | L11: =J11*K11 -> 5293750
C12: - Đệm đá dăm móng bệ mố M1 | D12: m3 | E12: 1 | F12: 6 | G12: 11 | H12: 0.1 | I12: 1 | J12: =E12*F12*G12*H12*I12 -> 6.6
C13: - Đệm đá dăm móng bệ mố M2 | D13: m3 | E13: 1 | F13: 6.5 | G13: 11 | H13: 0.1 | I13: 1 | J13: =E13*F13*G13*H13*I13 -> 7.15
A14: 3 | B14: AF.11111 | C14: Bê tông bệ móng mố mác 30MPa (M1, M2) | D14: m3 | J14: =SUM(J15:J16) -> 233.75 | K14: 1420000 | L14: =J14*K14 -> 331925000
C15: - Bệ móng mố M1 (chiều cao h=2.0m) | D15: m3 | E15: 1 | F15: 5 | G15: 11 | H15: 2 | I15: 1 | J15: =E15*F15*G15*H15*I15 -> 110
C16: - Bệ móng mố M2 (chiều cao h=2.25m) | D16: m3 | E16: 1 | F16: 5 | G16: 11 | H16: 2.25 | I16: 1 | J16: =E16*F16*G16*H16*I16 -> 123.75
A17: 4 | B17: AF.12111 | C17: Bê tông thân mố, tường ngực và đá kê gối mác 30MPa | D17: m3 | J17: =SUM(J18:J21) -> 31.46 | K17: 1480000 | L17: =J17*K17 -> 46560800
C18: - Thân mố M1 (kích thước 1.2m x 9.6m x 1.2m) | D18: m3 | E18: 1 | F18: 1.2 | G18: 9.6 | H18: 1.2 | I18: 1 | J18: =E18*F18*G18*H18*I18 -> 13.824
C19: - Thân mố M2 (kích thước 1.2m x 9.6m x 1.2m) | D19: m3 | E19: 1 | F19: 1.2 | G19: 9.6 | H19: 1.2 | I19: 1 | J19: =E19*F19*G19*H19*I19 -> 13.824
C20: - Tường ngực 2 đầu mố | D20: m3 | E20: 2 | F20: 0.4 | G20: 9.2 | H20: 0.45 | I20: 1 | J20: =E20*F20*G20*H20*I20 -> 3.312
C21: - Đá kê gối mố (8 vị trí kê gối dầm) | D21: m3 | E21: 8 | F21: 0.5 | G21: 0.5 | H21: 0.25 | I21: 1 | J21: =E21*F21*G21*H21*I21 -> 0.5
A22: 5 | B22: AF.12211 | C22: Bê tông 4 tường cánh mố dốc chéo mác 30MPa | D22: m3 | J22: =SUM(J23:J24) -> 55.2 | K22: 1480000 | L22: =J22*K22 -> 81696000
C23: - Bản thân tường cánh vát chéo (4 tường cánh) | D23: m3 | E23: 4 | F23: 7.5 | G23: 0.4 | H23: 4.8 | I23: 0.5 | J23: =E23*F23*G23*H23*I23 -> 28.8
C24: - Móng tường cánh mở rộng (4 móng) | D24: m3 | E24: 4 | F24: 5.5 | G24: 1.5 | H24: 0.8 | I24: 1 | J24: =E24*F24*G24*H24*I24 -> 26.4
A25: 6 | B25: AF.61210 | C25: Cốt thép bệ móng và thân mố M1, M2 (Lấy từ Bảng tổ hợp cắt thép) | D25: tấn | J25: =TO_HOP_CAT_THEP_11M7!K9/1000 -> 7.6810158 | K25: 22500000 | L25: =J25*K25 -> 1.7282286e+08
A26: 7 | B26: AL.11111 | C26: Khoan cấy thanh neo thép D32 ngàm bệ mố vào đá gốc | D26: thanh | J26: =SUM(J27:J28) -> 196 | K26: 185000 | L26: =J26*K26 -> 36260000
C27: - Thanh neo D32 bệ mố M1 cấy sâu 0.5m | D27: thanh | E27: 98 | F27: 1 | G27: 1 | H27: 1 | I27: 1 | J27: =E27*F27*G27*H27*I27 -> 98
C28: - Thanh neo D32 bệ mố M2 cấy sâu 0.5m | D28: thanh | E28: 98 | F28: 1 | G28: 1 | H28: 1 | I28: 1 | J28: =E28*F28*G28*H28*I28 -> 98
A29: PHẦN II: KẾT CẤU PHẦN TRÊN (DẦM T, MẶT CẦU, LAN CAN)
A30: 8 | B30: AF.31111 | C30: Bê tông dầm T L=15m mác 40MPa (4 phiến dầm) | D30: m3 | J30: =SUM(J31:J33) -> 40.7 | K30: 1750000 | L30: =J30*K30 -> 71225000
C31: - Bầu dầm T (4 phiến dầm) | D31: m3 | E31: 4 | F31: 14.8 | G31: 0.45 | H31: 0.35 | I31: 1 | J31: =E31*F31*G31*H31*I31 -> 9.324
C32: - Sườn dầm T (4 phiến dầm) | D32: m3 | E32: 4 | F32: 14.8 | G32: 0.2 | H32: 0.65 | I32: 1 | J32: =E32*F32*G32*H32*I32 -> 7.696
C33: - Bản cánh dầm T liên hợp (4 phiến dầm) | D33: m3 | E33: 4 | F33: 14.8 | G33: 2 | H33: 0.2 | I33: 1 | J33: =E33*F33*G33*H33*I33 -> 23.68
A34: 9 | B34: AF.61310 | C34: Cốt thép dầm T 15m (Thép chủ D32, đai D10, phân bố D14) | D34: tấn | J34: =TO_HOP_CAT_THEP_11M7!K13/1000 -> 6.740592 | K34: 23800000 | L34: =J34*K34 -> 1.6042609e+08
A35: 10 | B35: AF.21111 | C35: Bê tông bản mặt cầu và gờ chắn bánh mác 30MPa | D35: m3 | J35: =SUM(J36:J37) -> 20.475 | K35: 1550000 | L35: =J35*K35 -> 31736250
C36: - Bản mặt cầu liên hợp dày 14cm | D36: m3 | E36: 1 | F36: 15 | G36: 8.5 | H36: 0.14 | I36: 1 | J36: =E36*F36*G36*H36*I36 -> 17.85
C37: - Gờ chắn bánh và chân lan can 2 bên | D37: m3 | E37: 2 | F37: 15 | G37: 0.35 | H37: 0.25 | I37: 1 | J37: =E37*F37*G37*H37*I37 -> 2.625
A38: 11 | B38: AF.22210 | C38: Bê tông bản quá độ 2 đầu cầu L=4m mác 30MPa | D38: m3 | J38: =SUM(J39:J40) -> 22.08 | K38: 1480000 | L38: =J38*K38 -> 32678400
C39: - Bản quá độ mố M1 | D39: m3 | E39: 1 | F39: 4 | G39: 9.2 | H39: 0.3 | I39: 1 | J39: =E39*F39*G39*H39*I39 -> 11.04
C40: - Bản quá độ mố M2 | D40: m3 | E40: 1 | F40: 4 | G40: 9.2 | H40: 0.3 | I40: 1 | J40: =E40*F40*G40*H40*I40 -> 11.04
A41: 12 | B41: AL.21111 | C41: Gối cầu cao su bản thép cốt bản dầm T | D41: cái | E41: 8 | F41: 1 | G41: 1 | H41: 1 | I41: 1 | J41: =E41*F41*G41*H41*I41 -> 8 | K41: 3200000 | L41: =J41*K41 -> 25600000
A42: 13 | B42: AL.31111 | C42: Khe co giãn cao su cốt thép ray biên (2 vị trí mố) | D42: m | E42: 2 | F42: 9.2 | G42: 1 | H42: 1 | I42: 1 | J42: =E42*F42*G42*H42*I42 -> 18.4 | K42: 2800000 | L42: =J42*K42 -> 51520000
...

Sheet TONG_HOP_DU_TOAN_GXD
B2: BẢNG TỔNG HỢP KINH PHÍ DỰ TOÁN XÂY DỰNG (G_XD)
B3: Căn cứ Thông tư 11/2021/TT-BXD & Luật Xây dựng (Liên kết động từ Sheet QS)
A5: TT | B5: Khoản mục chi phí | C5: Cách tính / Căn cứ định mức | D5: Ký hiệu | E5: Giá trị (VNĐ)
A6: 1 | B6: Chi phí trực tiếp (Vật liệu, Nhân công, Máy) | C6: Link từ Sheet QS (Ô L55) | D6: T | E6: =QS_DIEN_GIAI_CHI_TIET!L55 -> 2.1523694e+09
A7: 2 | B7: Chi phí gián tiếp | C7: GT = T x 7,3% (Công trình giao thông theo tuyến) | D7: GT | E7: =E6*0.073 -> 1.5712297e+08
B8: - Chi phí chung | C8: 5,1% x T | D8: T_chung | E8: =E6*0.051 -> 1.0977084e+08
B9: - Chi phí xây dựng nhà tạm để ở và điều hành thi công | C9: 1,2% x T | D9: T_tam | E9: =E6*0.012 -> 25828433
B10: - Chi phí một số công việc không xác định được KL từ TK | C10: 1,0% x T | D10: T_kxd | E10: =E6*0.01 -> 21523694
A11: 3 | B11: Thu nhập chịu thuế tính trước | C11: TL = (T + GT) x 5,5% | D11: TL | E11: =(E6+E7)*0.055 -> 1.2702208e+08
A12: 4 | B12: Chi phí xây dựng trước thuế | C12: G = T + GT + TL | D12: G | E12: =E6+E7+E11 -> 2.4365144e+09
A13: 5 | B13: Thuế giá trị gia tăng (VAT) | C13: VAT = G x 8% | D13: VAT | E13: =E12*0.08 -> 1.9492116e+08
A14: 6 | B14: TỔNG CỘNG CHI PHÍ XÂY DỰNG DỰ TOÁN (G_XD) | C14: G_XD = G + VAT | D14: G_XD | E14: =E12+E13 -> 2.6314356e+09

Sheet TO_HOP_CAT_THEP_11M7
B2: BẢNG TỔ HỢP CẮT THÉP CÂY NGUYÊN 11.7m (1D CUTTING STOCK)
B3: Tối ưu hóa sơ đồ cắt, tính số lượng thanh, phôi thừa đề-xê (< 1.8%) và tổng khối lượng thép
A5: TT | B5: Cấu kiện sử dụng | C5: Ký hiệu đường kính (mm) | D5: Số lượng thanh (N) | E5: Dài 1 thanh L (m) | F5: Tổng chiều dài (m) = N x L | G5: Dài cây tiêu chuẩn (m) | H5: Số cây 11.7m cần dùng | I5: Chiều dài phôi (m) | J5: Đề-xê thừa (m) | K5: Tổng trọng lượng (kg) | L5: Tỷ lệ hao hụt (%)
A6: 1 | B6: Bệ móng M1, M2 - Thép chịu lực đáy | C6: 25 | D6: 140 | E6: 5.75 | F6: =D6*E6 -> 805 | G6: 11.7 | H6: =ROUNDUP(F6/G6, 0) -> 69 | I6: =H6*G6 -> 807.3 | J6: =I6-F6 -> 2.3 | K6: =F6*3.853 -> 3101.665 | L6: =(J6/I6)*100 -> 0.28490028
A7: 2 | B7: Bệ móng M1, M2 - Thép phân bố | C7: 22 | D7: 112 | E7: 10.6 | F7: =D7*E7 -> 1187.2 | G7: 11.7 | H7: =ROUNDUP(F7/G7, 0) -> 102 | I7: =H7*G7 -> 1193.4 | J7: =I7-F7 -> 6.2 | K7: =F7*2.984 -> 3542.6048 | L7: =(J7/I7)*100 -> 0.51952405
A8: 3 | B8: Bệ móng M1, M2 - Đai tăng cường | C8: 16 | D8: 180 | E8: 3.65 | F8: =D8*E8 -> 657 | G8: 11.7 | H8: =ROUNDUP(F8/G8, 0) -> 57 | I8: =H8*G8 -> 666.9 | J8: =I8-F8 -> 9.9 | K8: =F8*1.578 -> 1036.746 | L8: =(J8/I8)*100 -> 1.4844804
A9: TỔNG CỘNG THÉP MÓNG VÀ MỐ CẦU M1, M2 (LINK SANG SHEET QS) | K9: =SUM(K6:K8) -> 7681.0158
A10: 4 | B10: Dầm T 15m - Thép chủ chịu uốn (hàn nối so le) | C10: 32 | D10: 48 | E10: 14.8 | F10: =D10*E10 -> 710.4 | G10: 11.7 | H10: =ROUNDUP(F10/G10, 0) -> 61 | I10: =H10*G10 -> 713.7 | J10: =I10-F10 -> 3.3 | K10: =F10*6.313 -> 4484.7552 | L10: =(J10/I10)*100 -> 0.46237915
A11: 5 | B11: Dầm T 15m - Thép sườn chống nứt | C11: 14 | D11: 96 | E11: 14.6 | F11: =D11*E11 -> 1401.6 | G11: 11.7 | H11: =ROUNDUP(F11/G11, 0) -> 120 | I11: =H11*G11 -> 1404 | J11: =I11-F11 -> 2.4 | K11: =F11*1.208 -> 1693.1328 | L11: =(J11/I11)*100 -> 0.17094017
A12: 6 | B12: Dầm T 15m - Thép đai chống cắt | C12: 10 | D12: 320 | E12: 2.85 | F12: =D12*E12 -> 912 | G12: 11.7 | H12: =ROUNDUP(F12/G12, 0) -> 78 | I12: =H12*G12 -> 912.6 | J12: =I12-F12 -> 0.6 | K12: =F12*0.617 -> 562.704 | L12: =(J12/I12)*100 -> 0.06574622
A13: TỔNG CỘNG THÉP 4 PHIẾN DẦM T 15M (LINK SANG SHEET QS) | K13: =SUM(K10:K12) -> 6740.592
A14: 7 | B14: Tường chắn taluy - Thép đứng chịu lực | C14: 16 | D14: 160 | E14: 4.2 | F14: =D14*E14 -> 672 | G14: 11.7 | H14: =ROUNDUP(F14/G14, 0) -> 58 | I14: =H14*G14 -> 678.6 | J14: =I14-F14 -> 6.6 | K14: =F14*1.578 -> 1060.416 | L14: =(J14/I14)*100 -> 0.97259063
A15: 8 | B15: Tường chắn taluy - Thép đai phân bố | C15: 12 | D15: 220 | E15: 3.8 | F15: =D15*E15 -> 836 | G15: 11.7 | H15: =ROUNDUP(F15/G15, 0) -> 72 | I15: =H15*G15 -> 842.4 | J15: =I15-F15 -> 6.4 | K15: =F15*0.888 -> 742.368 | L15: =(J15/I15)*100 -> 0.75973409
A16: TỔNG CỘNG THÉP TƯỜNG CHẮN TALUY (LINK SANG SHEET QS) | K16: =SUM(K14:K15) -> 1802.784
A17: TỔNG CỘNG VẬT TƯ THÉP TOÀN DỰ ÁN | K17: =K9+K13+K16 -> 16224.392

Sheet KHOI_LUONG_DAO_DAP
B2: BẢNG TÍNH KHỐI LƯỢNG ĐÀO ĐẮP THEO MẶT CẮT TRẮC NGANG THIẾT KẾ
B3: Công thức tính thể tích: V = ((F1 + F2) / 2) x L (Liên kết động 100% sang Sheet Tiên lượng QS)
A5: TT | B5: Tên cọc | C5: Lý trình | D5: Khoảng cách L (m) | E5: Diện tích đào đất F_dat (m2) | F5: Khối lượng đất V_dat (m3) | G5: Diện tích đào đá F_da (m2) | H5: Khối lượng đá V_da (m3) | I5: Diện tích khuôn F_khuon (m2) | J5: Khối lượng khuôn V_khuon (m3)
A6: 1 | B6: TC227 | C6: Km14+300.00 | D6: 0 | E6: 18.5 | F6: 0 | G6: 12 | H6: 0 | I6: 1.2 | J6: 0
A7: 2 | B7: C407 | C7: Km14+320.00 | D7: 20 | E7: 24.2 | F7: =((E6+E7)/2)*D7 -> 427 | G7: 18.5 | H7: =((G6+G7)/2)*D7 -> 305 | I7: 1.2 | J7: =((I6+I7)/2)*D7 -> 24
A8: 3 | B8: C408 | C8: Km14+340.00 | D8: 20 | E8: 32 | F8: =((E7+E8)/2)*D8 -> 562 | G8: 26.4 | H8: =((G7+G8)/2)*D8 -> 449 | I8: 1.2 | J8: =((I7+I8)/2)*D8 -> 24
A9: 4 | B9: M1 (Mố 1) | C9: Km14+355.00 | D9: 15 | E9: 45.6 | F9: =((E8+E9)/2)*D9 -> 582 | G9: 42 | H9: =((G8+G9)/2)*D9 -> 513 | I9: 1.2 | J9: =((I8+I9)/2)*D9 -> 18
A10: 5 | B10: M2 (Mố 2) | C10: Km14+370.00 | D10: 15 | E10: 48.2 | F10: =((E9+E10)/2)*D10 -> 703.5 | G10: 45.5 | H10: =((G9+G10)/2)*D10 -> 656.25 | I10: 1.2 | J10: =((I9+I10)/2)*D10 -> 18
A11: 6 | B11: C409 | C11: Km14+385.00 | D11: 15 | E11: 28.4 | F11: =((E10+E11)/2)*D11 -> 574.5 | G11: 30.2 | H11: =((G10+G11)/2)*D11 -> 567.75 | I11: 1.2 | J11: =((I10+I11)/2)*D11 -> 18
A12: 7 | B12: P231 | C12: Km14+400.00 | D12: 15 | E12: 20.1 | F12: =((E11+E12)/2)*D12 -> 363.75 | G12: 19.8 | H12: =((G11+G12)/2)*D12 -> 375 | I12: 1.2 | J12: =((I11+I12)/2)*D12 -> 18
A13: 8 | B13: C410 | C13: Km14+415.00 | D13: 15 | E13: 15.2 | F13: =((E12+E13)/2)*D13 -> 264.75 | G13: 14.1 | H13: =((G12+G13)/2)*D13 -> 254.25 | I13: 1.2 | J13: =((I12+I13)/2)*D13 -> 18
A14: 9 | B14: C410A | C14: Km14+430.00 | D14: 15 | E14: 10.5 | F14: =((E13+E14)/2)*D14 -> 192.75 | G14: 8.4 | H14: =((G13+G14)/2)*D14 -> 168.75 | I14: 1.2 | J14: =((I13+I14)/2)*D14 -> 18
A15: 10 | B15: 410B | C15: Km14+440.00 | D15: 10 | E15: 6.2 | F15: =((E14+E15)/2)*D15 -> 83.5 | G15: 4 | H15: =((G14+G15)/2)*D15 -> 62 | I15: 1.2 | J15: =((I14+I15)/2)*D15 -> 12
A16: TỔNG CỘNG TOÀN TUYẾN (LINK SANG SHEET QS) | D16: =SUM(D6:D15) -> 140 | F16: =SUM(F6:F15) -> 3753.75 | H16: =SUM(H6:H15) -> 3351 | J16: =SUM(J6:J15) -> 168

Sheet TIEN_DO_THI_CONG_WBS
B2: DỰ ÁN: CẦU THÔN KHAI HOANG 2 (Km14+363,65 - ĐƯỜNG ĐỒNG VĂN - MỐC 456, HÀ GIANG)
B3: BẢNG TIẾN ĐỘ THI CÔNG CHI TIẾT WBS & BIỂU ĐỒ GANTT CHART TIẾN ĐỘ ĐƯỜNG GĂNG (CPM)
B4: Căn cứ Định mức dự toán TT 12/2021/TT-BXD, Luật Xây dựng 135/2025/QH15 & Nghị định 207/2026/NĐ-CP (Khối lượng link từ Sheet QS) | M4: THÁNG 10/2026 | Q4: THÁNG 11/2026 | U4: THÁNG 12/2026 | Y4: THÁNG 01/2027 | AC4: THÁNG 02/2027 | AG4: THÁNG 03/2027
A5: Mã WBS | B5: Danh mục công tác thi công | C5: Khối lượng | D5: ĐVT | E5: Định mức (công/ĐVT) | F5: Tổng công (công) | G5: Tổ đội (người) | H5: Thời gian Duration | I5: Ngày bắt đầu Start | J5: Ngày xong Finish | K5: Quan hệ Predecessors | L5: Đường găng CPM | M5: T1 | N5: T2 | O5: T3 | P5: T4 | Q5: T5 | R5: T6 | S5: T7 | T5: T8 | U5: T9 | V5: T10 | W5: T11 | X5: T12 | Y5: T13 | Z5: T14 | AA5: T15 | AB5: T16 | AC5: T17 | AD5: T18 | AE5: T19 | AF5: T20 | AG5: T21 | AH5: T22 | AI5: T23 | AJ5: T24 | AK5: T25
M6: 01/10 | N6: 08/10 | O6: 15/10 | P6: 22/10 | Q6: 29/10 | R6: 05/11 | S6: 12/11 | T6: 19/11 | U6: 26/11 | V6: 03/12 | W6: 10/12 | X6: 17/12 | Y6: 24/12 | Z6: 31/12 | AA6: 07/01 | AB6: 14/01 | AC6: 21/01 | AD6: 28/01 | AE6: 04/02 | AF6: 11/02 | AG6: 18/02 | AH6: 25/02 | AI6: 04/03 | AJ6: 11/03 | AK6: 18/03
A7: 1.0 | H7: 19 ngày | I7: 01/10/2026 | J7: 19/10/2026 | L7: YES | M7: ▬ | N7: ▬ | O7: ▬
A8: 1.1 | B8: Bàn giao tim mốc, cọc cao độ mốc tọa độ VN2000 | C8: 1 | D8: Điểm | E8: 8 | F8: =C8*E8 -> 8 | G8: 4 | H8: =ROUNDUP(F8/G8, 0) -> 2 | I8: 2026-10-01 | J8: 2026-10-02 | K8: - | L8: YES | M8: █
A9: 1.2 | B9: Rà phá bom mìn, dọn dẹp mặt bằng thi công & lán trại | C9: =QS_DIEN_GIAI_CHI_TIET!J54 -> 1040 | D9: m2 | E9: 0.04 | F9: =C9*E9 -> 41.6 | G9: 6 | H9: =ROUNDUP(F9/G9, 0) -> 7 | I9: 2026-10-03 | J9: 2026-10-07 | K9: 1.1FS | L9: YES | M9: █
A10: 1.3 | B10: Thi công đường công vụ vượt suối, bãi đúc dầm & bãi tập kết | C10: 1 | D10: Hệ | E10: 120 | F10: =C10*E10 -> 120 | G10: 10 | H10: =ROUNDUP(F10/G10, 0) -> 12 | I10: 2026-10-08 | J10: 2026-10-19 | K10: 1.2FS | L10: YES | N10: █ | O10: █
A11: 2.0 | H11: 75 ngày | I11: 20/10/2026 | J11: 03/01/2027 | L11: YES | O11: ▬ | P11: ▬ | Q11: ▬ | R11: ▬ | S11: ▬ | T11: ▬ | U11: ▬ | V11: ▬ | W11: ▬ | X11: ▬ | Y11: ▬ | Z11: ▬
A12: 2.1 | B12: Đào hố móng bệ mố M1, M2 ngàm vào nền đá gốc | C12: =QS_DIEN_GIAI_CHI_TIET!J7 -> 76.25 | D12: m3 | E12: 0.35 | F12: =C12*E12 -> 26.6875 | G12: 12 | H12: =ROUNDUP(F12/G12, 0) -> 3 | I12: 2026-10-20 | J12: 2026-10-27 | K12: 1.3FS | L12: YES | O12: █ | P12: █
A13: 2.2 | B13: Khoan lỗ và cắm 98 thanh thép neo D32 L=1.0m | C13: 98 | D13: Thanh | E13: 0.25 | F13: =C13*E13 -> 24.5 | G13: 6 | H13: =ROUNDUP(F13/G13, 0) -> 5 | I13: 2026-10-28 | J13: 2026-11-01 | K13: 2.1FS | L13: YES | P13: █ | Q13: █
A14: 2.3 | B14: Rải đá dăm đệm và đổ bê tông lót đáy bệ móng mố | C14: =QS_DIEN_GIAI_CHI_TIET!J10 -> 7.5 | D14: m3 | E14: 0.85 | F14: =C14*E14 -> 6.375 | G14: 8 | H14: =ROUNDUP(F14/G14, 0) -> 1 | I14: 2026-11-02 | J14: 2026-11-03 | K14: 2.2FS | L14: YES | Q14: █
A15: 2.4 | B15: Gia công lắp dựng cốt thép bệ móng mố M1, M2 (D16, D22, D25) | C15: =QS_DIEN_GIAI_CHI_TIET!J13 -> 7.15 | D15: Tấn | E15: 3.2 | F15: =C15*E15 -> 22.88 | G15: 10 | H15: =ROUNDUP(F15/G15, 0) -> 3 | I15: 2026-11-04 | J15: 2026-11-08 | K15: 2.3FS | L15: YES | Q15: █ | R15: █
A16: 2.5 | B16: Lắp dựng ván khuôn bệ móng mố M1, M2 | C16: 185 | D16: m2 | E16: 0.32 | F16: =C16*E16 -> 59.2 | G16: 8 | H16: =ROUNDUP(F16/G16, 0) -> 8 | I16: 2026-11-09 | J16: 2026-11-15 | K16: 2.4FS | L16: YES | R16: █ | S16: █
A17: 2.6 | B17: Đổ bê tông bệ móng mố M1, M2 (30 MPa kết hợp đầm dùi) | C17: =QS_DIEN_GIAI_CHI_TIET!J17 -> 31.46 | D17: m3 | E17: 0.42 | F17: =C17*E17 -> 13.2132 | G17: 16 | H17: =ROUNDUP(F17/G17, 0) -> 1 | I17: 2026-11-16 | J17: 2026-11-22 | K17: 2.5FS | L17: YES | S17: █ | T17: █
A18: 2.7 | B18: Bảo dưỡng bê tông bệ móng mố (chờ đạt cường độ R7) | C18: 1 | D18: Đợt | E18: 7 | F18: =C18*E18 -> 7 | G18: 1 | H18: 7 | I18: 2026-11-23 | J18: 2026-11-29 | K18: 2.6FS | L18: YES | T18: █ | U18: █
A19: 2.8 | B19: Gia công lắp dựng cốt thép thân mố, tường cánh, tường đỉnh M1, M2 | C19: =QS_DIEN_GIAI_CHI_TIET!J23 -> 28.8 | D19: Tấn | E19: 3.45 | F19: =C19*E19 -> 99.36 | G19: 10 | H19: =ROUNDUP(F19/G19, 0) -> 10 | I19: 2026-11-30 | J19: 2026-12-04 | K19: 2.7FS | L19: YES | U19: █ | V19: █
A20: 2.9 | B20: Lắp dựng ván khuôn thân mố, tường cánh và xà mũ mố | C20: 260 | D20: m2 | E20: 0.35 | F20: =C20*E20 -> 91 | G20: 10 | H20: =ROUNDUP(F20/G20, 0) -> 10 | I20: 2026-12-05 | J20: 2026-12-13 | K20: 2.8FS | L20: YES | V20: █ | W20: █
A21: 2.10 | B21: Đổ bê tông thân mố, tường cánh, tường đỉnh M1, M2 (30 MPa) | C21: =QS_DIEN_GIAI_CHI_TIET!J20 -> 3.312 | D21: m3 | E21: 0.52 | F21: =C21*E21 -> 1.72224 | G21: 14 | H21: =ROUNDUP(F21/G21, 0) -> 1 | I21: 2026-12-14 | J21: 2026-12-16 | K21: 2.9FS | L21: YES | W21: █
A22: 2.11 | B22: Đổ bê tông đá kê gối & lắp đặt 8 gối cao su bản thép | C22: 8 | D22: Bộ | E22: 1.8 | F22: =C22*E22 -> 14.4 | G22: 4 | H22: =ROUNDUP(F22/G22, 0) -> 4 | I22: 2026-12-17 | J22: 2026-12-20 | K22: 2.10FS | L22: YES | W22: █ | X22: █
A23: 2.12 | B23: Đắp đất chọn lọc lòng mố (K98) & quét nhựa đường chống thấm | C23: =QS_DIEN_GIAI_CHI_TIET!J26 -> 196 | D23: m3 | E23: 0.28 | F23: =C23*E23 -> 54.88 | G23: 8 | H23: =ROUNDUP(F23/G23, 0) -> 7 | I23: 2026-12-21 | J23: 2027-01-03 | K23: 2.11FS | L23: NO | X23: █ | Y23: █ | Z23: █
A24: 3.0 | H24: 79 ngày | I24: 20/11/2026 | J24: 06/02/2027 | L24: YES | T24: ▬ | U24: ▬ | V24: ▬ | W24: ▬ | X24: ▬ | Y24: ▬ | Z24: ▬ | AA24: ▬ | AB24: ▬ | AC24: ▬ | AD24: ▬ | AE24: ▬
A25: 3.1 | B25: Gia công lắp dựng cốt thép 4 phiến dầm T L=15m tại bãi đúc | C25: =QS_DIEN_GIAI_CHI_TIET!J32 -> 7.696 | D25: Tấn | E25: 3.8 | F25: =C25*E25 -> 29.2448 | G25: 12 | H25: =ROUNDUP(F25/G25, 0) -> 3 | I25: 2026-11-20 | J25: 2026-12-22 | K25: 2.6SS+3d | L25: NO | T25: █ | U25: █ | V25: █ | W25: █ | X25: █
A26: 3.2 | B26: Lắp dựng ván khuôn thép định hình dầm T 15m | C26: 320 | D26: m2 | E26: 0.3 | F26: =C26*E26 -> 96 | G26: 8 | H26: =ROUNDUP(F26/G26, 0) -> 12 | I26: 2026-12-23 | J26: 2027-01-03 | K26: 3.1FS | L26: NO | X26: █ | Y26: █ | Z26: █
A27: 3.3 | B27: Đổ bê tông 4 phiến dầm T 15m (Bê tông C40/C35 mác cao) | C27: =QS_DIEN_GIAI_CHI_TIET!J29 -> 0 | D27: m3 | E27: 0.65 | F27: =C27*E27 -> 0 | G27: 14 | H27: =ROUNDUP(F27/G27, 0) -> 0 | I27: 2027-01-04 | J27: 2027-01-05 | K27: 3.2FS | L27: NO | Z27: █
A28: 3.4 | B28: Dưỡng hộ bê tông dầm T đủ 28 ngày đạt cường độ thiết kế | C28: 1 | D28: Đợt | E28: 28 | F28: =C28*E28 -> 28 | G28: 1 | H28: 28 | I28: 2027-01-06 | J28: 2027-02-02 | K28: 3.3FS | L28: YES | Z28: █ | AA28: █ | AB28: █ | AC28: █ | AD28: █
A29: 3.5 | B29: Vận chuyển và cẩu lắp 4 phiến dầm T vào vị trí mố M1, M2 | C29: 4 | D29: Phiến | E29: 4 | F29: =C29*E29 -> 16 | G29: 8 | H29: =ROUNDUP(F29/G29, 0) -> 2 | I29: 2027-02-03 | J29: 2027-02-04 | K29: 2.11FS,3.4FS | L29: YES | AD29: █
A30: 3.6 | B30: Lắp cốt thép, ván khuôn & đổ bê tông dầm ngang, mối nối ướt | C30: =QS_DIEN_GIAI_CHI_TIET!J36 -> 17.85 | D30: m3 | E30: 1.2 | F30: =C30*E30 -> 21.42 | G30: 8 | H30: =ROUNDUP(F30/G30, 0) -> 3 | I30: 2027-02-05 | J30: 2027-02-06 | K30: 3.5FS | L30: YES | AD30: █ | AE30: █
A31: 4.0 | H31: 45 ngày | I31: 07/02/2027 | J31: 23/03/2027 | L31: YES | AE31: ▬ | AF31: ▬ | AG31: ▬ | AH31: ▬ | AI31: ▬ | AJ31: ▬ | AK31: ▬
A32: 4.1 | B32: Lắp dựng cốt thép bản mặt cầu (lưới thép D6) & ván khuôn treo | C32: =QS_DIEN_GIAI_CHI_TIET!J42 -> 18.4 | D32: Tấn | E32: 4.2 | F32: =C32*E32 -> 77.28 | G32: 8 | H32: =ROUNDUP(F32/G32, 0) -> 10 | I32: 2027-02-07 | J32: 2027-02-08 | K32: 3.6FS | L32: YES | AE32: █
A33: 4.2 | B33: Đổ bê tông bản mặt cầu tại chỗ (Bê tông 30 MPa) | C33: =QS_DIEN_GIAI_CHI_TIET!J39 -> 11.04 | D33: m3 | E33: 0.55 | F33: =C33*E33 -> 6.072 | G33: 16 | H33: =ROUNDUP(F33/G33, 0) -> 1 | I33: 2027-02-09 | J33: 2027-02-10 | K33: 4.1FS | L33: YES | AE33: █
A34: 4.3 | B34: Dưỡng hộ bê tông bản mặt cầu (chờ đạt cường độ R14) | C34: 1 | D34: Đợt | E34: 14 | F34: =C34*E34 -> 14 | G34: 1 | H34: 14 | I34: 2027-02-11 | J34: 2027-02-24 | K34: 4.2FS | L34: YES | AE34: █ | AF34: █ | AG34: █
A35: 4.4 | B35: Đổ gờ lan can bê tông, lắp dựng lan can thép mạ kẽm & ống thoát D150 | C35: =QS_DIEN_GIAI_CHI_TIET!J45 -> 3753.75 | D35: md | E35: 0.45 | F35: =C35*E35 -> 1689.1875 | G35: 6 | H35: =ROUNDUP(F35/G35, 0) -> 282 | I35: 2027-02-25 | J35: 2027-02-27 | K35: 4.3FS | L35: NO | AG35: █ | AH35: █
A36: 4.5 | B36: Lắp đặt 02 khe co giãn thép răng lược HP50 & chèn vữa 50 MPa | C36: =QS_DIEN_GIAI_CHI_TIET!J47 -> 168 | D36: md | E36: 1.5 | F36: =C36*E36 -> 252 | G36: 6 | H36: =ROUNDUP(F36/G36, 0) -> 42 | I36: 2027-02-28 | J36: 2027-03-03 | K36: 4.3FS | L36: YES | AH36: █
A37: 4.6 | B37: Phun lớp chống thấm mặt cầu & thảm bê tông nhựa C12.5 dày 7cm | C37: =QS_DIEN_GIAI_CHI_TIET!J49 -> 40 | D37: m2 | E37: 0.05 | F37: =C37*E37 -> 2 | G37: 8 | H37: =ROUNDUP(F37/G37, 0) -> 1 | I37: 2027-03-04 | J37: 2027-03-04 | K37: 4.5FS | L37: YES | AH37: █
A38: 4.7 | B38: Thi công 2 bản quá độ BTCT 25 MPa & đắp đất chuyển tiếp K95 | C38: =QS_DIEN_GIAI_CHI_TIET!J51 -> 12 | D38: m3 | E38: 0.85 | F38: =C38*E38 -> 10.2 | G38: 10 | H38: =ROUNDUP(F38/G38, 0) -> 2 | I38: 2027-03-05 | J38: 2027-03-06 | K38: 4.6FS | L38: YES | AH38: █ | AI38: █
A39: 4.8 | B39: Gia cố ốp mái taluy mố bằng BTXM 20 MPa dày 20cm & tường chắn | C39: 65 | D39: m3 | E39: 0.75 | F39: =C39*E39 -> 48.75 | G39: 10 | H39: =ROUNDUP(F39/G39, 0) -> 5 | I39: 2027-03-07 | J39: 2027-03-11 | K39: 4.7FS | L39: NO | AI39: █
A40: 4.9 | B40: Thi công kết cấu nền mặt đường hai đầu cầu nối tuyến | C40: 1 | D40: Gói | E40: 80 | F40: =C40*E40 -> 80 | G40: 10 | H40: =ROUNDUP(F40/G40, 0) -> 8 | I40: 2027-03-12 | J40: 2027-03-19 | K40: 4.7FS | L40: YES | AI40: █ | AJ40: █
A41: 4.10 | B41: Thử tải cầu, kiểm định tĩnh/động & nghiệm thu bàn giao | C41: 1 | D41: Gói | E41: 24 | F41: =C41*E41 -> 24 | G41: 6 | H41: =ROUNDUP(F41/G41, 0) -> 4 | I41: 2027-03-20 | J41: 2027-03-23 | K41: 4.9FS | L41: YES | AJ41: █ | AK41: █
...

Sheet HOSO_KCS_NGHIEM_THU
B2: DANH MỤC HỒ SƠ QUẢN LÝ CHẤT LƯỢNG & BIÊN BẢN NGHIỆM THU KCS
B3: Tuân thủ Luật Xây dựng 135/2025/QH15 & Nghị định 207/2026/NĐ-CP (Khối lượng link từ Sheet QS)
A5: STT | B5: Số hiệu biên bản | C5: Tên công việc / Giai đoạn nghiệm thu | D5: Khối lượng nghiệm thu | E5: ĐVT | F5: Căn cứ quy chuẩn / Tiêu chuẩn áp dụng | G5: Chỉ tiêu thí nghiệm / Kiểm tra KCS
A6: 1 | B6: BBNT-01 | C6: Bàn giao mốc tim tuyến, cọc mốc cao độ và mặt bằng | D6: 1 | E6: Điểm | F6: TCVN 9393:2012 | G6: Sai số tim mốc <= 5mm, cao độ <= 2mm
A7: 2 | B7: BBNT-02 | C7: Rà phá bom mìn, vật nổ và dọn dẹp mặt bằng lán trại | D7: =QS_DIEN_GIAI_CHI_TIET!J54 -> 1040 | E7: m2 | F7: QCVN 01:2010/BQP | G7: Biên bản nghiệm thu sạch nổ 100% diện tích
A8: 3 | B8: BBNT-03 | C8: Kiểm tra nghiệm thu chất lượng vật liệu đầu vào | D8: 1 | E8: Lô | F8: TCVN 1651:2018 | G8: Kéo uốn thép, chứng chỉ CO/CQ xi măng, đá cát
A9: 4 | B9: BBNT-04 | C9: Nghiệm thu hố móng ngàm vào đá gốc bệ mố M1, M2 | D9: =QS_DIEN_GIAI_CHI_TIET!J7 -> 76.25 | E9: m3 | F9: TCVN 4447:2012 | G9: Độ sâu ngàm đá gốc >= 0.5m, dọn sạch đáy móng
A10: 5 | B10: BBNT-05 | C10: Nghiệm thu khoan cấy thanh neo thép D32 vào nền đá | D10: =QS_DIEN_GIAI_CHI_TIET!J26 -> 196 | E10: thanh | F10: TCVN 8163:2009 | G10: Cấy sâu >= 0.5m, thử kéo nhổ neo đạt 100% P_tk
A11: 6 | B11: BBNT-06 | C11: Nghiệm thu ván khuôn, cốt thép bệ móng mố M1, M2 | D11: =QS_DIEN_GIAI_CHI_TIET!J25 -> 7.6810158 | E11: tấn | F11: TCVN 4453:1995 | G11: Khoảng cách cốt thép +-10mm, ván khuôn kín khít
A12: 7 | B12: BBNT-07 | C12: Nghiệm thu đổ bê tông bệ móng mố M1, M2 30MPa | D12: =QS_DIEN_GIAI_CHI_TIET!J14 -> 233.75 | E12: m3 | F12: TCVN 3105:2022 | G12: Độ sụt 12+-2cm, đúc 6 tổ mẫu nén R7, R28
A13: 8 | B13: BBNT-08 | C13: Nghiệm thu thân mố, tường ngực và đá kê gối 30MPa | D13: =QS_DIEN_GIAI_CHI_TIET!J17 -> 31.46 | E13: m3 | F13: TCVN 11823:2017 | G13: Kích thước hình học, tim đá kê gối sai số <= 3mm
A14: 9 | B14: BBNT-09 | C14: Nghiệm thu ván khuôn, cốt thép, bê tông tường cánh | D14: =QS_DIEN_GIAI_CHI_TIET!J22 -> 55.2 | E14: m3 | F14: TCVN 4453:1995 | G14: Góc dốc tường cánh chéo, chiều dày lớp bảo vệ
A15: 10 | B15: BBNT-10 | C15: Nghiệm thu cốt thép dầm T 15m mác 40MPa | D15: =QS_DIEN_GIAI_CHI_TIET!J34 -> 6.740592 | E15: tấn | F15: TCVN 1651:2018 | G15: Mối hàn so le thanh chủ D32, đai D10 buộc chắc chắn
A16: 11 | B16: BBNT-11 | C16: Nghiệm thu đổ bê tông 4 phiến dầm T 15m 40MPa | D16: =QS_DIEN_GIAI_CHI_TIET!J30 -> 40.7 | E16: m3 | F16: TCVN 3105:2022 | G16: Bảo dưỡng ẩm 14 ngày, cường độ R28 >= 40MPa
A17: 12 | B17: BBNT-12 | C17: Nghiệm thu lắp đặt gối chậu cao su và lao dầm T | D17: =QS_DIEN_GIAI_CHI_TIET!J41 -> 8 | E17: cái | F17: TCVN 10308:2014 | G17: Cao độ gối +-2mm, 4 phiến dầm đặt êm thuận
A18: 13 | B18: BBNT-13 | C18: Nghiệm thu ván khuôn, cốt thép, bê tông bản mặt cầu | D18: =QS_DIEN_GIAI_CHI_TIET!J35 -> 20.475 | E18: m3 | F18: TCVN 11823:2017 | G18: Dày bản 14cm, độ dốc ngang thoát nước 2%
A19: 14 | B19: BBNT-14 | C19: Nghiệm thu bản quá độ 2 đầu cầu mác 30MPa | D19: =QS_DIEN_GIAI_CHI_TIET!J38 -> 22.08 | E19: m3 | F19: TCVN 4453:1995 | G19: Lắp đặt 2 đầu mố L=4m, đầm chặt lớp đệm
A20: 15 | B20: BBNT-15 | C20: Nghiệm thu lan can thép mạ kẽm và khe co giãn | D20: =QS_DIEN_GIAI_CHI_TIET!J43 -> 30 | E20: m | F20: TCVN 5408:2007 | G20: Chiều dày mạ kẽm nhúng nóng >= 100 micron
A21: 16 | B21: BBNT-16 | C21: Nghiệm thu tường chắn taluy đợt 1-4 mác 25MPa | D21: =QS_DIEN_GIAI_CHI_TIET!J48 -> 86.5 | E21: m3 | F21: TCVN 4453:1995 | G21: Ống thoát nước PVC D110 bố trí so le cự ly 2m
A22: 17 | B22: BBNT-17 | C22: Nghiệm thu đào nền đường và đào phá đá mở rộng | D22: =QS_DIEN_GIAI_CHI_TIET!J45 -> 3753.75 | E22: m3 | F22: TCVN 4447:2012 | G22: Cao độ đáy nền đường, độ dốc mái taluy đào
A23: 18 | B23: BBNT-18 | C23: Nghiệm thu hoàn thành công trình đưa vào sử dụng | D23: 1 | E23: Công trình | F23: Nghị định 207/2026/NĐ-CP | G23: Thử tải cầu tĩnh & động, kiểm tra hồ sơ hoàn công

Sheet BIEU_DO_GANTT
A1: BIỂU ĐỒ GANTT – DỰ ÁN CẦU THÔN KHAI HOANG 2
A2: Nguồn dữ liệu: TIEN_DO_THI_CONG_WBS | Ngày bắt đầu/kết thúc và CPM lấy trực tiếp từ WBS
A4: STT | B4: Mã WBS | C4: Tên công việc / Giai đoạn | D4: Khối lượng | E4: ĐVT | F4: Ngày bắt đầu | G4: Thời lượng (ngày) | H4: Ngày kết thúc | I4: Nhãn Gantt | J4: Offset | K4: Duration
A5: =TIEN_DO_THI_CONG_WBS!A7 -> 1.0 | B5: =TIEN_DO_THI_CONG_WBS!A7 -> 1.0 | C5: =TIEN_DO_THI_CONG_WBS!B7 -> 0 | D5: =TIEN_DO_THI_CONG_WBS!C7 -> 0 | E5: =TIEN_DO_THI_CONG_WBS!D7 -> 0 | F5: =TIEN_DO_THI_CONG_WBS!I7 -> 01/10/2026 | G5: =H5-F5+1 -> 19 | H5: =TIEN_DO_THI_CONG_WBS!J7 -> 19/10/2026 | I5: =IF(C5="",B5&" - Giai đoạn",B5&" - "&C5) -> 1.0 - 0 | J5: =F5-$F$5 -> 0 | K5: =G5 -> 19
A6: =TIEN_DO_THI_CONG_WBS!A8 -> 1.1 | B6: =TIEN_DO_THI_CONG_WBS!A8 -> 1.1 | C6: =TIEN_DO_THI_CONG_WBS!B8 -> Bàn giao tim mốc, cọc cao độ mốc tọa độ VN2000 | D6: =TIEN_DO_THI_CONG_WBS!C8 -> 1 | E6: =TIEN_DO_THI_CONG_WBS!D8 -> Điểm | F6: =TIEN_DO_THI_CONG_WBS!I8 -> 2026-10-01 | G6: =H6-F6+1 -> 2 | H6: =TIEN_DO_THI_CONG_WBS!J8 -> 2026-10-02 | I6: =IF(C6="",B6&" - Giai đoạn",B6&" - "&C6) -> 1.1 - Bàn giao tim mốc, cọc cao độ mốc tọa độ VN2000 | J6: =F6-$F$5 -> 0 | K6: =G6 -> 2
A7: =TIEN_DO_THI_CONG_WBS!A9 -> 1.2 | B7: =TIEN_DO_THI_CONG_WBS!A9 -> 1.2 | C7: =TIEN_DO_THI_CONG_WBS!B9 -> Rà phá bom mìn, dọn dẹp mặt bằng thi công & lán trại | D7: =TIEN_DO_THI_CONG_WBS!C9 -> 1040 | E7: =TIEN_DO_THI_CONG_WBS!D9 -> m2 | F7: =TIEN_DO_THI_CONG_WBS!I9 -> 2026-10-03 | G7: =H7-F7+1 -> 5 | H7: =TIEN_DO_THI_CONG_WBS!J9 -> 2026-10-07 | I7: =IF(C7="",B7&" - Giai đoạn",B7&" - "&C7) -> 1.2 - Rà phá bom mìn, dọn dẹp mặt bằng thi công & lán trại | J7: =F7-$F$5 -> 2 | K7: =G7 -> 5
A8: =TIEN_DO_THI_CONG_WBS!A10 -> 1.3 | B8: =TIEN_DO_THI_CONG_WBS!A10 -> 1.3 | C8: =TIEN_DO_THI_CONG_WBS!B10 -> Thi công đường công vụ vượt suối, bãi đúc dầm & bãi tập kết | D8: =TIEN_DO_THI_CONG_WBS!C10 -> 1 | E8: =TIEN_DO_THI_CONG_WBS!D10 -> Hệ | F8: =TIEN_DO_THI_CONG_WBS!I10 -> 2026-10-08 | G8: =H8-F8+1 -> 12 | H8: =TIEN_DO_THI_CONG_WBS!J10 -> 2026-10-19 | I8: =IF(C8="",B8&" - Giai đoạn",B8&" - "&C8) -> 1.3 - Thi công đường công vụ vượt suối, bãi đúc dầm & bãi tập kết | J8: =F8-$F$5 -> 7 | K8: =G8 -> 12
A9: =TIEN_DO_THI_CONG_WBS!A11 -> 2.0 | B9: =TIEN_DO_THI_CONG_WBS!A11 -> 2.0 | C9: =TIEN_DO_THI_CONG_WBS!B11 -> 0 | D9: =TIEN_DO_THI_CONG_WBS!C11 -> 0 | E9: =TIEN_DO_THI_CONG_WBS!D11 -> 0 | F9: =TIEN_DO_THI_CONG_WBS!I11 -> 20/10/2026 | G9: =H9-F9+1 -> 76 | H9: =TIEN_DO_THI_CONG_WBS!J11 -> 03/01/2027 | I9: =IF(C9="",B9&" - Giai đoạn",B9&" - "&C9) -> 2.0 - 0 | J9: =F9-$F$5 -> 19 | K9: =G9 -> 76
A10: =TIEN_DO_THI_CONG_WBS!A12 -> 2.1 | B10: =TIEN_DO_THI_CONG_WBS!A12 -> 2.1 | C10: =TIEN_DO_THI_CONG_WBS!B12 -> Đào hố móng bệ mố M1, M2 ngàm vào nền đá gốc | D10: =TIEN_DO_THI_CONG_WBS!C12 -> 76.25 | E10: =TIEN_DO_THI_CONG_WBS!D12 -> m3 | F10: =TIEN_DO_THI_CONG_WBS!I12 -> 2026-10-20 | G10: =H10-F10+1 -> 8 | H10: =TIEN_DO_THI_CONG_WBS!J12 -> 2026-10-27 | I10: =IF(C10="",B10&" - Giai đoạn",B10&" - "&C10) -> 2.1 - Đào hố móng bệ mố M1, M2 ngàm vào nền đá gốc | J10: =F10-$F$5 -> 19 | K10: =G10 -> 8
A11: =TIEN_DO_THI_CONG_WBS!A13 -> 2.2 | B11: =TIEN_DO_THI_CONG_WBS!A13 -> 2.2 | C11: =TIEN_DO_THI_CONG_WBS!B13 -> Khoan lỗ và cắm 98 thanh thép neo D32 L=1.0m | D11: =TIEN_DO_THI_CONG_WBS!C13 -> 98 | E11: =TIEN_DO_THI_CONG_WBS!D13 -> Thanh | F11: =TIEN_DO_THI_CONG_WBS!I13 -> 2026-10-28 | G11: =H11-F11+1 -> 5 | H11: =TIEN_DO_THI_CONG_WBS!J13 -> 2026-11-01 | I11: =IF(C11="",B11&" - Giai đoạn",B11&" - "&C11) -> 2.2 - Khoan lỗ và cắm 98 thanh thép neo D32 L=1.0m | J11: =F11-$F$5 -> 27 | K11: =G11 -> 5
A12: =TIEN_DO_THI_CONG_WBS!A14 -> 2.3 | B12: =TIEN_DO_THI_CONG_WBS!A14 -> 2.3 | C12: =TIEN_DO_THI_CONG_WBS!B14 -> Rải đá dăm đệm và đổ bê tông lót đáy bệ móng mố | D12: =TIEN_DO_THI_CONG_WBS!C14 -> 7.5 | E12: =TIEN_DO_THI_CONG_WBS!D14 -> m3 | F12: =TIEN_DO_THI_CONG_WBS!I14 -> 2026-11-02 | G12: =H12-F12+1 -> 2 | H12: =TIEN_DO_THI_CONG_WBS!J14 -> 2026-11-03 | I12: =IF(C12="",B12&" - Giai đoạn",B12&" - "&C12) -> 2.3 - Rải đá dăm đệm và đổ bê tông lót đáy bệ móng mố | J12: =F12-$F$5 -> 32 | K12: =G12 -> 2
A13: =TIEN_DO_THI_CONG_WBS!A15 -> 2.4 | B13: =TIEN_DO_THI_CONG_WBS!A15 -> 2.4 | C13: =TIEN_DO_THI_CONG_WBS!B15 -> Gia công lắp dựng cốt thép bệ móng mố M1, M2 (D16, D22, D25) | D13: =TIEN_DO_THI_CONG_WBS!C15 -> 7.15 | E13: =TIEN_DO_THI_CONG_WBS!D15 -> Tấn | F13: =TIEN_DO_THI_CONG_WBS!I15 -> 2026-11-04 | G13: =H13-F13+1 -> 5 | H13: =TIEN_DO_THI_CONG_WBS!J15 -> 2026-11-08 | I13: =IF(C13="",B13&" - Giai đoạn",B13&" - "&C13) -> 2.4 - Gia công lắp dựng cốt thép bệ móng mố M1, M2 (D16, D22, D25) | J13: =F13-$F$5 -> 34 | K13: =G13 -> 5
A14: =TIEN_DO_THI_CONG_WBS!A16 -> 2.5 | B14: =TIEN_DO_THI_CONG_WBS!A16 -> 2.5 | C14: =TIEN_DO_THI_CONG_WBS!B16 -> Lắp dựng ván khuôn bệ móng mố M1, M2 | D14: =TIEN_DO_THI_CONG_WBS!C16 -> 185 | E14: =TIEN_DO_THI_CONG_WBS!D16 -> m2 | F14: =TIEN_DO_THI_CONG_WBS!I16 -> 2026-11-09 | G14: =H14-F14+1 -> 7 | H14: =TIEN_DO_THI_CONG_WBS!J16 -> 2026-11-15 | I14: =IF(C14="",B14&" - Giai đoạn",B14&" - "&C14) -> 2.5 - Lắp dựng ván khuôn bệ móng mố M1, M2 | J14: =F14-$F$5 -> 39 | K14: =G14 -> 7
A15: =TIEN_DO_THI_CONG_WBS!A17 -> 2.6 | B15: =TIEN_DO_THI_CONG_WBS!A17 -> 2.6 | C15: =TIEN_DO_THI_CONG_WBS!B17 -> Đổ bê tông bệ móng mố M1, M2 (30 MPa kết hợp đầm dùi) | D15: =TIEN_DO_THI_CONG_WBS!C17 -> 31.46 | E15: =TIEN_DO_THI_CONG_WBS!D17 -> m3 | F15: =TIEN_DO_THI_CONG_WBS!I17 -> 2026-11-16 | G15: =H15-F15+1 -> 7 | H15: =TIEN_DO_THI_CONG_WBS!J17 -> 2026-11-22 | I15: =IF(C15="",B15&" - Giai đoạn",B15&" - "&C15) -> 2.6 - Đổ bê tông bệ móng mố M1, M2 (30 MPa kết hợp đầm dùi) | J15: =F15-$F$5 -> 46 | K15: =G15 -> 7
A16: =TIEN_DO_THI_CONG_WBS!A18 -> 2.7 | B16: =TIEN_DO_THI_CONG_WBS!A18 -> 2.7 | C16: =TIEN_DO_THI_CONG_WBS!B18 -> Bảo dưỡng bê tông bệ móng mố (chờ đạt cường độ R7) | D16: =TIEN_DO_THI_CONG_WBS!C18 -> 1 | E16: =TIEN_DO_THI_CONG_WBS!D18 -> Đợt | F16: =TIEN_DO_THI_CONG_WBS!I18 -> 2026-11-23 | G16: =H16-F16+1 -> 7 | H16: =TIEN_DO_THI_CONG_WBS!J18 -> 2026-11-29 | I16: =IF(C16="",B16&" - Giai đoạn",B16&" - "&C16) -> 2.7 - Bảo dưỡng bê tông bệ móng mố (chờ đạt cường độ R7) | J16: =F16-$F$5 -> 53 | K16: =G16 -> 7
... A39: =TIEN_DO_THI_CONG_WBS!A41 -> 4.10 | B39: =TIEN_DO_THI_CONG_WBS!A41 -> 4.10 | C39: =TIEN_DO_THI_CONG_WBS!B41 -> Thử tải cầu, kiểm định tĩnh/động & nghiệm thu bàn giao | D39: =TIEN_DO_THI_CONG_WBS!C41 -> 1 | E39: =TIEN_DO_THI_CONG_WBS!D41 -> Gói | F39: =TIEN_DO_THI_CONG_WBS!I41 -> 2027-03-20 | G39: =H39-F39+1 -> 4 | H39: =TIEN_DO_THI_CONG_WBS!J41 -> 2027-03-23 | I39: =IF(C39="",B39&" - Giai đoạn",B39&" - "&C39) -> 4.10 - Thử tải cầu, kiểm định tĩnh/động & nghiệm thu bàn giao | J39: =F39-$F$5 -> 170 | K39: =G39 -> 4
